## 开始执行... 2022-04-27 15:15:00

Traceback (most recent call last):
  File "/usr/lib/python3.9/site-packages/urllib3/connectionpool.py", line 699, in urlopen
    httplib_response = self._make_request(
  File "/usr/lib/python3.9/site-packages/urllib3/connectionpool.py", line 445, in _make_request
    six.raise_from(e, None)
  File "<string>", line 3, in raise_from
  File "/usr/lib/python3.9/site-packages/urllib3/connectionpool.py", line 440, in _make_request
    httplib_response = conn.getresponse()
  File "/usr/lib/python3.9/http/client.py", line 1371, in getresponse
    response.begin()
  File "/usr/lib/python3.9/http/client.py", line 319, in begin
    version, status, reason = self._read_status()
  File "/usr/lib/python3.9/http/client.py", line 280, in _read_status
    line = str(self.fp.readline(_MAXLINE + 1), "iso-8859-1")
  File "/usr/lib/python3.9/socket.py", line 704, in readinto
    return self._sock.recv_into(b)
ConnectionResetError: [Errno 104] Connection reset by peer

During handling of the above exception, another exception occurred:

Traceback (most recent call last):
  File "/usr/lib/python3.9/site-packages/requests/adapters.py", line 439, in send
    resp = conn.urlopen(
  File "/usr/lib/python3.9/site-packages/urllib3/connectionpool.py", line 755, in urlopen
    retries = retries.increment(
  File "/usr/lib/python3.9/site-packages/urllib3/util/retry.py", line 532, in increment
    raise six.reraise(type(error), error, _stacktrace)
  File "/usr/lib/python3.9/site-packages/urllib3/packages/six.py", line 769, in reraise
    raise value.with_traceback(tb)
  File "/usr/lib/python3.9/site-packages/urllib3/connectionpool.py", line 699, in urlopen
    httplib_response = self._make_request(
  File "/usr/lib/python3.9/site-packages/urllib3/connectionpool.py", line 445, in _make_request
    six.raise_from(e, None)
  File "<string>", line 3, in raise_from
  File "/usr/lib/python3.9/site-packages/urllib3/connectionpool.py", line 440, in _make_request
    httplib_response = conn.getresponse()
  File "/usr/lib/python3.9/http/client.py", line 1371, in getresponse
    response.begin()
  File "/usr/lib/python3.9/http/client.py", line 319, in begin
    version, status, reason = self._read_status()
  File "/usr/lib/python3.9/http/client.py", line 280, in _read_status
    line = str(self.fp.readline(_MAXLINE + 1), "iso-8859-1")
  File "/usr/lib/python3.9/socket.py", line 704, in readinto
    return self._sock.recv_into(b)
urllib3.exceptions.ProtocolError: ('Connection aborted.', ConnectionResetError(104, 'Connection reset by peer'))

During handling of the above exception, another exception occurred:

Traceback (most recent call last):
  File "/ql/data/scripts/daily_push/english.py", line 56, in <module>
    push_content_to_users()
  File "/ql/data/scripts/daily_push/english.py", line 48, in push_content_to_users
    get_dict = get_random_VanEnglishSentence(APIKEY)
  File "/ql/data/scripts/daily_push/english.py", line 39, in get_random_VanEnglishSentence
    r = requests.get(url)
  File "/usr/lib/python3.9/site-packages/requests/api.py", line 75, in get
    return request('get', url, params=params, **kwargs)
  File "/usr/lib/python3.9/site-packages/requests/api.py", line 61, in request
    return session.request(method=method, url=url, **kwargs)
  File "/usr/lib/python3.9/site-packages/requests/sessions.py", line 542, in request
    resp = self.send(prep, **send_kwargs)
  File "/usr/lib/python3.9/site-packages/requests/sessions.py", line 677, in send
    history = [resp for resp in gen]
  File "/usr/lib/python3.9/site-packages/requests/sessions.py", line 677, in <listcomp>
    history = [resp for resp in gen]
  File "/usr/lib/python3.9/site-packages/requests/sessions.py", line 237, in resolve_redirects
    resp = self.send(
  File "/usr/lib/python3.9/site-packages/requests/sessions.py", line 655, in send
    r = adapter.send(request, **kwargs)
  File "/usr/lib/python3.9/site-packages/requests/adapters.py", line 498, in send
    raise ConnectionError(err, request=request)
requests.exceptions.ConnectionError: ('Connection aborted.', ConnectionResetError(104, 'Connection reset by peer'))

## 执行结束... 2022-04-27 15:15:01 耗时 1 秒
